/*
Throwing an exception from a function called from within a try block.
*/

#include <iostream>
using namespace std;

int main() {



}